<?xml version="1.0" ?>
<!-- =================================================================================== -->
<!-- |    This document was autogenerated by xacro from em_3905.urdf.xacro             | -->
<!-- |    EDITING THIS FILE BY HAND IS NOT RECOMMENDED                                 | -->
<!-- =================================================================================== -->
<robot name="em_3905">
  <material name="battery_mat">
    <color rgba="0 0 1 1"/>
  </material>
  <material name="chassis_mat">
    <color rgba="0.5 0.5 0.5 1"/>
  </material>
  <material name="tire_mat">
    <color rgba="0 0 0 1"/>
  </material>
  <!-- base_link must have geometry so that its axes can be displayed in
       rviz. -->
  <link name="base_link">
    <visual>
      <geometry>
        <box size="0.01 0.01 0.01"/>
      </geometry>
      <material name="chassis_mat"/>
    </visual>
  </link>
  <gazebo reference="base_link">
    <material>Gazebo/Grey</material>
  </gazebo>
  <!-- Chassis -->
  <link name="chassis">
    <visual>
      <origin xyz="0 0 -0.005"/>
      <geometry>
        <box size="0.258 0.168 0.01"/>
      </geometry>
      <material name="chassis_mat"/>
    </visual>
    <collision>
      <origin xyz="0 0 -0.005"/>
      <geometry>
        <box size="0.258 0.168 0.01"/>
      </geometry>
    </collision>
    <inertial>
      <origin xyz="0 0 -0.005"/>
      <mass value="2.788"/>
      <inertia ixx="0.0065806093333333334" ixy="0" ixz="0" iyy="0.015488269333333332" iyz="0" izz="0.022022411999999995"/>
    </inertial>
  </link>
  <gazebo reference="chassis">
    <material>Gazebo/Purple</material>
  </gazebo>
  <joint name="base_link_to_chasis" type="fixed">
    <parent link="base_link"/>
    <child link="chassis"/>
  </joint>
  <!-- Upper Part-->
  <link name="upper">
    <visual>
      <origin xyz="0 0 0.11499999999999999"/>
      <geometry>
        <box size="0.258 0.168 0.01"/>
      </geometry>
      <material name="chassis_mat"/>
    </visual>
    <collision>
      <origin xyz="0 0 0.11499999999999999"/>
      <geometry>
        <box size="0.258 0.168 0.01"/>
      </geometry>
    </collision>
    <inertial>
      <origin xyz="0 0 -0.005"/>
      <mass value="2.788"/>
      <inertia ixx="0.0065806093333333334" ixy="0" ixz="0" iyy="0.015488269333333332" iyz="0" izz="0.022022411999999995"/>
    </inertial>
  </link>
  <gazebo reference="upper">
    <material>Gazebo/White</material>
  </gazebo>
  <joint name="base_link_to_upper" type="fixed">
    <parent link="base_link"/>
    <child link="upper"/>
  </joint>
  <!-- Upper Part2-->
  <link name="upper_two">
    <visual>
      <origin xyz="0 0 0.235"/>
      <geometry>
        <box size="0.258 0.1 0.01"/>
      </geometry>
      <material name="chassis_mat"/>
    </visual>
    <collision>
      <origin xyz="0 0 0.235"/>
      <geometry>
        <box size="0.258 0.1 0.01"/>
      </geometry>
    </collision>
    <inertial>
      <origin xyz="0 0 -0.005"/>
      <mass value="2.788"/>
      <inertia ixx="0.0023465666666666668" ixy="0" ixz="0" iyy="0.015488269333333332" iyz="0" izz="0.01778836933333333"/>
    </inertial>
  </link>
  <gazebo reference="upper_two">
    <material>Gazebo/White</material>
  </gazebo>
  <joint name="base_link_to_upper_two" type="fixed">
    <parent link="base_link"/>
    <child link="upper_two"/>
  </joint>
  <!--"""""""""""""""""""""""""""""""""""""""""""""""""""""""""""""""""""""""""""""""""-->
  <!--Leg 01-->
  <link name="leg01">
    <collision>
      <origin xyz="0.08 0.05 0.055"/>
      <geometry>
        <cylinder length="0.11" radius="0.005"/>
      </geometry>
    </collision>
    <visual>
      <origin xyz="0.08 0.05 0.055"/>
      <geometry>
        <cylinder length="0.11" radius="0.004"/>
      </geometry>
    </visual>
    <inertial>
      <mass value="0.001"/>
      <inertia ixx="0.001" ixy="0" ixz="0" iyy="0.001" iyz="0" izz="0.001"/>
    </inertial>
  </link>
  <joint name="base_link_to_leg01" type="fixed">
    <parent link="base_link"/>
    <child link="leg01"/>
  </joint>
  <gazebo reference="leg01">
    <material value="Gazebo/White"/>
  </gazebo>
  <!--Leg 02-->
  <link name="leg02">
    <collision>
      <origin xyz="-0.08 0.05 0.055"/>
      <geometry>
        <cylinder length="0.11" radius="0.005"/>
      </geometry>
    </collision>
    <visual>
      <origin xyz="-0.08 0.05 0.055"/>
      <geometry>
        <cylinder length="0.11" radius="0.004"/>
      </geometry>
    </visual>
    <inertial>
      <mass value="0.001"/>
      <inertia ixx="0.001" ixy="0" ixz="0" iyy="0.001" iyz="0" izz="0.001"/>
    </inertial>
  </link>
  <joint name="base_link_to_leg02" type="fixed">
    <parent link="base_link"/>
    <child link="leg02"/>
  </joint>
  <gazebo reference="leg02">
    <material value="Gazebo/White"/>
  </gazebo>
  <!--Leg 03-->
  <link name="leg03">
    <collision>
      <origin xyz="-0.08 -0.05 0.055"/>
      <geometry>
        <cylinder length="0.11" radius="0.005"/>
      </geometry>
    </collision>
    <visual>
      <origin xyz="-0.08 -0.05 0.055"/>
      <geometry>
        <cylinder length="0.11" radius="0.004"/>
      </geometry>
    </visual>
    <inertial>
      <mass value="0.001"/>
      <inertia ixx="0.001" ixy="0" ixz="0" iyy="0.001" iyz="0" izz="0.001"/>
    </inertial>
  </link>
  <joint name="base_link_to_leg03" type="fixed">
    <parent link="base_link"/>
    <child link="leg03"/>
  </joint>
  <gazebo reference="leg03">
    <material value="Gazebo/White"/>
  </gazebo>
  <!--Leg 04-->
  <link name="leg04">
    <collision>
      <origin xyz="0.08 -0.05 0.055"/>
      <geometry>
        <cylinder length="0.11" radius="0.005"/>
      </geometry>
    </collision>
    <visual>
      <origin xyz="0.08 -0.05 0.055"/>
      <geometry>
        <cylinder length="0.11" radius="0.004"/>
      </geometry>
    </visual>
    <inertial>
      <mass value="0.001"/>
      <inertia ixx="0.001" ixy="0" ixz="0" iyy="0.001" iyz="0" izz="0.001"/>
    </inertial>
  </link>
  <joint name="base_link_to_leg04" type="fixed">
    <parent link="base_link"/>
    <child link="leg04"/>
  </joint>
  <gazebo reference="leg04">
    <material value="Gazebo/White"/>
  </gazebo>
  <!--Leg 1-->
  <link name="leg1">
    <collision>
      <origin xyz="0.07 0.04 0.175"/>
      <geometry>
        <cylinder length="0.11" radius="0.005"/>
      </geometry>
    </collision>
    <visual>
      <origin xyz="0.07 0.04 0.175"/>
      <geometry>
        <cylinder length="0.11" radius="0.004"/>
      </geometry>
    </visual>
    <inertial>
      <mass value="0.001"/>
      <inertia ixx="0.001" ixy="0" ixz="0" iyy="0.001" iyz="0" izz="0.001"/>
    </inertial>
  </link>
  <joint name="base_link_to_leg1" type="fixed">
    <parent link="base_link"/>
    <child link="leg1"/>
  </joint>
  <gazebo reference="leg1">
    <material value="Gazebo/White"/>
  </gazebo>
  <!--Leg 2-->
  <link name="leg2">
    <collision>
      <origin xyz="-0.07 0.04 0.175"/>
      <geometry>
        <cylinder length="0.11" radius="0.005"/>
      </geometry>
    </collision>
    <visual>
      <origin xyz="-0.07 0.04 0.175"/>
      <geometry>
        <cylinder length="0.11" radius="0.004"/>
      </geometry>
    </visual>
    <inertial>
      <mass value="0.001"/>
      <inertia ixx="0.001" ixy="0" ixz="0" iyy="0.001" iyz="0" izz="0.001"/>
    </inertial>
  </link>
  <joint name="base_link_to_leg2" type="fixed">
    <parent link="base_link"/>
    <child link="leg2"/>
  </joint>
  <gazebo reference="leg2">
    <material value="Gazebo/White"/>
  </gazebo>
  <!--Leg 3-->
  <link name="leg3">
    <collision>
      <origin xyz="-0.07 -0.04 0.175"/>
      <geometry>
        <cylinder length="0.11" radius="0.005"/>
      </geometry>
    </collision>
    <visual>
      <origin xyz="-0.07 -0.04 0.175"/>
      <geometry>
        <cylinder length="0.11" radius="0.004"/>
      </geometry>
    </visual>
    <inertial>
      <mass value="0.001"/>
      <inertia ixx="0.001" ixy="0" ixz="0" iyy="0.001" iyz="0" izz="0.001"/>
    </inertial>
  </link>
  <joint name="base_link_to_leg3" type="fixed">
    <parent link="base_link"/>
    <child link="leg3"/>
  </joint>
  <gazebo reference="leg3">
    <material value="Gazebo/White"/>
  </gazebo>
  <!--Leg 4-->
  <link name="leg4">
    <collision>
      <origin xyz="0.07 -0.04 0.175"/>
      <geometry>
        <cylinder length="0.11" radius="0.005"/>
      </geometry>
    </collision>
    <visual>
      <origin xyz="0.07 -0.04 0.175"/>
      <geometry>
        <cylinder length="0.11" radius="0.004"/>
      </geometry>
    </visual>
    <inertial>
      <mass value="0.001"/>
      <inertia ixx="0.001" ixy="0" ixz="0" iyy="0.001" iyz="0" izz="0.001"/>
    </inertial>
  </link>
  <joint name="base_link_to_leg4" type="fixed">
    <parent link="base_link"/>
    <child link="leg4"/>
  </joint>
  <gazebo reference="leg4">
    <material value="Gazebo/White"/>
  </gazebo>
  <!--LIDAR GAZEBO HOKUYO-->
  <link name="laser_link">
    <collision>
      <origin xyz="0 0 0"/>
      <geometry>
        <cylinder length="0.025" radius="0.025"/>
      </geometry>
    </collision>
    <visual>
      <origin xyz="0 0 0"/>
      <geometry>
        <cylinder length="0.025" radius="0.025"/>
      </geometry>
    </visual>
    <inertial>
      <mass value="0.001"/>
      <inertia ixx="0.001" ixy="0" ixz="0" iyy="0.001" iyz="0" izz="0.001"/>
    </inertial>
  </link>
  <joint name="base_link_to_laser" type="fixed">
    <origin xyz="-0.03 0 0.25"/>
    <parent link="base_link"/>
    <child link="laser_link"/>
  </joint>
  <gazebo reference="laser_link">
    <material value="Gazebo/Grey"/>
    <sensor name="head_hokuyo_sensor" type="ray">
      <pose>0 0 0 0 0 0</pose>
      <visualize>false</visualize>
      <update_rate>10.0</update_rate>
      <ray>
        <scan>
          <horizontal>
            <samples>720</samples>
            <resolution>1</resolution>
            <min_angle>-3.1415</min_angle>
            <max_angle>3.1415</max_angle>
          </horizontal>
        </scan>
        <range>
          <min>0.50</min>
          <max>8.0</max>
          <resolution>0.01</resolution>
        </range>
        <noise>
          <type>gaussian</type>
          <!-- Noise parameters based on published spec for Hokuyo laser
             achieving "+-30mm" accuracy at range < 10m.  A mean of 0.0m and
             stddev of 0.01m will put 99.7% of samples within 0.03m of the true
             reading. -->
          <mean>0.0</mean>
          <stddev>0.01</stddev>
        </noise>
      </ray>
      <plugin filename="libgazebo_ros_laser.so" name="gazebo_ros_head_hokuyo_controller">
        <topicName>scan</topicName>
        <frameName>laser_link</frameName>
      </plugin>
    </sensor>
  </gazebo>
  <!--CAMERA-->
  <link name="camera_link">
    <collision>
      <origin rpy="0 0 0" xyz="0 0 0"/>
      <geometry>
        <box size="0.001 0.02 0.02"/>
      </geometry>
    </collision>
    <visual>
      <origin rpy="0 0 0" xyz="0 0 0"/>
      <geometry>
        <box size="0.001 0.02 0.02"/>
      </geometry>
    </visual>
    <inertial>
      <mass value="0.001"/>
      <inertia ixx="0.001" ixy="0" ixz="0" iyy="0.001" iyz="0" izz="0.001"/>
    </inertial>
  </link>
  <joint name="base_link_to_camera" type="fixed">
    <origin rpy="0 0 0" xyz="0.13 0.0 0.24"/>
    <parent link="base_link"/>
    <child link="camera_link"/>
  </joint>
  <gazebo reference="camera_link">
    <material value="Gazebo/Green"/>
    <sensor name="camera" type="depth">
      <update_rate>20</update_rate>
      <camera>
        <horizontal_fov>1.047198</horizontal_fov>
        <image>
          <width>640</width>
          <height>480</height>
          <format>R8G8B8</format>
        </image>
        <clip>
          <near>0.05</near>
          <far>3</far>
        </clip>
      </camera>
      <plugin filename="libgazebo_ros_openni_kinect.so" name="camera_controller">
        <baseline>0.2</baseline>
        <alwaysOn>true</alwaysOn>
        <updateRate>1.0</updateRate>
        <cameraName>camera_ir</cameraName>
        <imageTopicName>/camera/color/image_raw</imageTopicName>
        <cameraInfoTopicName>/camera/color/camera_info</cameraInfoTopicName>
        <depthImageTopicName>/camera/depth/image_raw</depthImageTopicName>
        <depthImageInfoTopicName>/camera/depth/camera_info</depthImageInfoTopicName>
        <pointCloudTopicName>/camera/depth/points</pointCloudTopicName>
        <frameName>camera_link</frameName>
        <pointCloudCutoff>0.5</pointCloudCutoff>
        <pointCloudCutoffMax>3.0</pointCloudCutoffMax>
        <distortionK1>0.00000001</distortionK1>
        <distortionK2>0.00000001</distortionK2>
        <distortionK3>0.00000001</distortionK3>
        <distortionT1>0.00000001</distortionT1>
        <distortionT2>0.00000001</distortionT2>
        <CxPrime>0</CxPrime>
        <Cx>0</Cx>
        <Cy>0</Cy>
        <focalLength>0</focalLength>
        <hackBaseline>0</hackBaseline>
      </plugin>
    </sensor>
  </gazebo>
  <joint name="left_front_shock" type="prismatic">
    <parent link="chassis"/>
    <child link="left_steering_link"/>
    <origin xyz="0.1675                    0.1525                    -0.0235"/>
    <axis xyz="0 0 -1"/>
    <limit effort="12.5106" lower="-0.042" upper="0.042" velocity="1000"/>
  </joint>
  <transmission name="left_front_shock_trans">
    <type>transmission_interface/SimpleTransmission</type>
    <joint name="left_front_shock">
      <hardwareInterface>hardware_interface/EffortJointInterface</hardwareInterface>
    </joint>
    <actuator name="left_front_shock_act">
      <hardwareInterface>hardware_interface/EffortJointInterface</hardwareInterface>
      <mechanicalReduction>1</mechanicalReduction>
    </actuator>
  </transmission>
  <link name="left_steering_link">
    <inertial>
      <mass value="0.001"/>
      <inertia ixx="0.001" ixy="0" ixz="0" iyy="0.001" iyz="0" izz="0.001"/>
    </inertial>
  </link>
  <joint name="left_steering_joint" type="revolute">
    <parent link="left_steering_link"/>
    <child link="left_front_axle_carrier"/>
    <axis xyz="0 0 1"/>
    <limit effort="0.5649" lower="-0.785398163" upper="0.785398163" velocity="4.553"/>
  </joint>
  <transmission name="left_steering_trans">
    <type>transmission_interface/SimpleTransmission</type>
    <joint name="left_steering_joint">
      <hardwareInterface>hardware_interface/EffortJointInterface</hardwareInterface>
    </joint>
    <actuator name="left_front_shock_act">
      <hardwareInterface>hardware_interface/EffortJointInterface</hardwareInterface>
      <mechanicalReduction>1</mechanicalReduction>
    </actuator>
  </transmission>
  <link name="left_front_axle_carrier">
    <inertial>
      <mass value="0.001"/>
      <inertia ixx="0.001" ixy="0" ixz="0" iyy="0.001" iyz="0" izz="0.001"/>
    </inertial>
  </link>
  <!-- The left and right axles have the same axis so that identical
         rotation values cause the wheels to rotate in the same direction. -->
  <joint name="left_front_axle" type="continuous">
    <parent link="left_front_axle_carrier"/>
    <child link="left_front_wheel"/>
    <origin rpy="1.57079633 0 0"/>
    <axis xyz="0 0 -1"/>
    <limit effort="5.12766" velocity="244.8696"/>
  </joint>
  <transmission name="left_front_axle_trans">
    <type>transmission_interface/SimpleTransmission</type>
    <joint name="left_front_axle">
      <hardwareInterface>hardware_interface/EffortJointInterface</hardwareInterface>
    </joint>
    <actuator name="left_front_axle_act">
      <hardwareInterface>hardware_interface/EffortJointInterface</hardwareInterface>
      <mechanicalReduction>1</mechanicalReduction>
    </actuator>
  </transmission>
  <link name="left_front_wheel">
    <visual>
      <origin xyz="0                      -6.938893903907228e-18                      0"/>
      <geometry>
        <cylinder length="0.0889" radius="0.073025"/>
      </geometry>
      <material name="tire_mat"/>
    </visual>
    <collision>
      <origin xyz="0                      -6.938893903907228e-18                      0"/>
      <geometry>
        <cylinder length="0.0889" radius="0.073025"/>
      </geometry>
    </collision>
    <inertial>
      <mass value="0.29"/>
      <inertia ixx="0.0007464659129791666" ixy="0" ixz="0" iyy="0.0007464659129791666" iyz="0" izz="0.001110943342625"/>
    </inertial>
  </link>
  <gazebo reference="left_front_wheel">
    <material>Gazebo/Black</material>
  </gazebo>
  <joint name="right_front_shock" type="prismatic">
    <parent link="chassis"/>
    <child link="right_steering_link"/>
    <origin xyz="0.1675                    -0.1525                    -0.0235"/>
    <axis xyz="0 0 -1"/>
    <limit effort="12.5106" lower="-0.042" upper="0.042" velocity="1000"/>
  </joint>
  <transmission name="right_front_shock_trans">
    <type>transmission_interface/SimpleTransmission</type>
    <joint name="right_front_shock">
      <hardwareInterface>hardware_interface/EffortJointInterface</hardwareInterface>
    </joint>
    <actuator name="right_front_shock_act">
      <hardwareInterface>hardware_interface/EffortJointInterface</hardwareInterface>
      <mechanicalReduction>1</mechanicalReduction>
    </actuator>
  </transmission>
  <link name="right_steering_link">
    <inertial>
      <mass value="0.001"/>
      <inertia ixx="0.001" ixy="0" ixz="0" iyy="0.001" iyz="0" izz="0.001"/>
    </inertial>
  </link>
  <joint name="right_steering_joint" type="revolute">
    <parent link="right_steering_link"/>
    <child link="right_front_axle_carrier"/>
    <axis xyz="0 0 1"/>
    <limit effort="0.5649" lower="-0.785398163" upper="0.785398163" velocity="4.553"/>
  </joint>
  <transmission name="right_steering_trans">
    <type>transmission_interface/SimpleTransmission</type>
    <joint name="right_steering_joint">
      <hardwareInterface>hardware_interface/EffortJointInterface</hardwareInterface>
    </joint>
    <actuator name="right_front_shock_act">
      <hardwareInterface>hardware_interface/EffortJointInterface</hardwareInterface>
      <mechanicalReduction>1</mechanicalReduction>
    </actuator>
  </transmission>
  <link name="right_front_axle_carrier">
    <inertial>
      <mass value="0.001"/>
      <inertia ixx="0.001" ixy="0" ixz="0" iyy="0.001" iyz="0" izz="0.001"/>
    </inertial>
  </link>
  <!-- The left and right axles have the same axis so that identical
         rotation values cause the wheels to rotate in the same direction. -->
  <joint name="right_front_axle" type="continuous">
    <parent link="right_front_axle_carrier"/>
    <child link="right_front_wheel"/>
    <origin rpy="1.57079633 0 0"/>
    <axis xyz="0 0 -1"/>
    <limit effort="5.12766" velocity="244.8696"/>
  </joint>
  <transmission name="right_front_axle_trans">
    <type>transmission_interface/SimpleTransmission</type>
    <joint name="right_front_axle">
      <hardwareInterface>hardware_interface/EffortJointInterface</hardwareInterface>
    </joint>
    <actuator name="right_front_axle_act">
      <hardwareInterface>hardware_interface/EffortJointInterface</hardwareInterface>
      <mechanicalReduction>1</mechanicalReduction>
    </actuator>
  </transmission>
  <link name="right_front_wheel">
    <visual>
      <origin xyz="0                      6.938893903907228e-18                      0"/>
      <geometry>
        <cylinder length="0.0889" radius="0.073025"/>
      </geometry>
      <material name="tire_mat"/>
    </visual>
    <collision>
      <origin xyz="0                      6.938893903907228e-18                      0"/>
      <geometry>
        <cylinder length="0.0889" radius="0.073025"/>
      </geometry>
    </collision>
    <inertial>
      <mass value="0.29"/>
      <inertia ixx="0.0007464659129791666" ixy="0" ixz="0" iyy="0.0007464659129791666" iyz="0" izz="0.001110943342625"/>
    </inertial>
  </link>
  <gazebo reference="right_front_wheel">
    <material>Gazebo/Black</material>
  </gazebo>
  <joint name="left_rear_shock" type="prismatic">
    <parent link="chassis"/>
    <child link="left_rear_axle_carrier"/>
    <origin xyz="-0.1675                    0.1525                    -0.0235"/>
    <axis xyz="0 0 -1"/>
    <limit effort="12.5106" lower="-0.042" upper="0.042" velocity="1000"/>
  </joint>
  <transmission name="left_rear_shock_trans">
    <type>transmission_interface/SimpleTransmission</type>
    <joint name="left_rear_shock">
      <hardwareInterface>hardware_interface/EffortJointInterface</hardwareInterface>
    </joint>
    <actuator name="left_rear_shock_act">
      <hardwareInterface>hardware_interface/EffortJointInterface</hardwareInterface>
      <mechanicalReduction>1</mechanicalReduction>
    </actuator>
  </transmission>
  <link name="left_rear_axle_carrier">
    <inertial>
      <mass value="0.001"/>
      <inertia ixx="0.001" ixy="0" ixz="0" iyy="0.001" iyz="0" izz="0.001"/>
    </inertial>
  </link>
  <!-- The left and right axles have the same axis so that identical
         rotation values cause the wheels to rotate in the same direction. -->
  <joint name="left_rear_axle" type="continuous">
    <parent link="left_rear_axle_carrier"/>
    <child link="left_rear_wheel"/>
    <origin rpy="1.57079633 0 0"/>
    <axis xyz="0 0 -1"/>
    <limit effort="5.12766" velocity="244.8696"/>
  </joint>
  <transmission name="left_rear_axle_trans">
    <type>transmission_interface/SimpleTransmission</type>
    <joint name="left_rear_axle">
      <hardwareInterface>hardware_interface/EffortJointInterface</hardwareInterface>
    </joint>
    <actuator name="left_rear_axle_act">
      <hardwareInterface>hardware_interface/EffortJointInterface</hardwareInterface>
      <mechanicalReduction>1</mechanicalReduction>
    </actuator>
  </transmission>
  <link name="left_rear_wheel">
    <visual>
      <origin xyz="0                      -6.938893903907228e-18                      0"/>
      <geometry>
        <cylinder length="0.0889" radius="0.073025"/>
      </geometry>
      <material name="tire_mat"/>
    </visual>
    <collision>
      <origin xyz="0                      -6.938893903907228e-18                      0"/>
      <geometry>
        <cylinder length="0.0889" radius="0.073025"/>
      </geometry>
    </collision>
    <inertial>
      <mass value="0.29"/>
      <inertia ixx="0.0007464659129791666" ixy="0" ixz="0" iyy="0.0007464659129791666" iyz="0" izz="0.001110943342625"/>
    </inertial>
  </link>
  <gazebo reference="left_rear_wheel">
    <material>Gazebo/Black</material>
  </gazebo>
  <joint name="right_rear_shock" type="prismatic">
    <parent link="chassis"/>
    <child link="right_rear_axle_carrier"/>
    <origin xyz="-0.1675                    -0.1525                    -0.0235"/>
    <axis xyz="0 0 -1"/>
    <limit effort="12.5106" lower="-0.042" upper="0.042" velocity="1000"/>
  </joint>
  <transmission name="right_rear_shock_trans">
    <type>transmission_interface/SimpleTransmission</type>
    <joint name="right_rear_shock">
      <hardwareInterface>hardware_interface/EffortJointInterface</hardwareInterface>
    </joint>
    <actuator name="right_rear_shock_act">
      <hardwareInterface>hardware_interface/EffortJointInterface</hardwareInterface>
      <mechanicalReduction>1</mechanicalReduction>
    </actuator>
  </transmission>
  <link name="right_rear_axle_carrier">
    <inertial>
      <mass value="0.001"/>
      <inertia ixx="0.001" ixy="0" ixz="0" iyy="0.001" iyz="0" izz="0.001"/>
    </inertial>
  </link>
  <!-- The left and right axles have the same axis so that identical
         rotation values cause the wheels to rotate in the same direction. -->
  <joint name="right_rear_axle" type="continuous">
    <parent link="right_rear_axle_carrier"/>
    <child link="right_rear_wheel"/>
    <origin rpy="1.57079633 0 0"/>
    <axis xyz="0 0 -1"/>
    <limit effort="5.12766" velocity="244.8696"/>
  </joint>
  <transmission name="right_rear_axle_trans">
    <type>transmission_interface/SimpleTransmission</type>
    <joint name="right_rear_axle">
      <hardwareInterface>hardware_interface/EffortJointInterface</hardwareInterface>
    </joint>
    <actuator name="right_rear_axle_act">
      <hardwareInterface>hardware_interface/EffortJointInterface</hardwareInterface>
      <mechanicalReduction>1</mechanicalReduction>
    </actuator>
  </transmission>
  <link name="right_rear_wheel">
    <visual>
      <origin xyz="0                      6.938893903907228e-18                      0"/>
      <geometry>
        <cylinder length="0.0889" radius="0.073025"/>
      </geometry>
      <material name="tire_mat"/>
    </visual>
    <collision>
      <origin xyz="0                      6.938893903907228e-18                      0"/>
      <geometry>
        <cylinder length="0.0889" radius="0.073025"/>
      </geometry>
    </collision>
    <inertial>
      <mass value="0.29"/>
      <inertia ixx="0.0007464659129791666" ixy="0" ixz="0" iyy="0.0007464659129791666" iyz="0" izz="0.001110943342625"/>
    </inertial>
  </link>
  <gazebo reference="right_rear_wheel">
    <material>Gazebo/Black</material>
  </gazebo>
  <gazebo>
    <plugin filename="libgazebo_ros_control.so" name="gazebo_ros_control">
      <robotSimType>gazebo_ros_control/DefaultRobotHWSim</robotSimType>
      <!-- As of 10/7/13, setting controlPeriod to a value greater than
           Gazebo's simulation period prevents the shock absorbers from
           working.
      <controlPeriod>${ctrl_period}</controlPeriod>
      -->
    </plugin>
  </gazebo>
</robot>
